<?xml version="1.0" ?>
<robot name="single_leg">
    <link name="rail">
        <visual>
            <origin xyz=" 0 0 0" rpy="0 0 0" />
            <geometry>
                <mesh filename="package://single_leg_description/meshes/rail.STL"/>
            </geometry>
            <material name="yellow">
                <color rgba="1 0.4 0 1"/>
            </material>
        </visual>
    </link>
    <joint name="parallel_rail" type="prismatic">
        <parent link="rail"/>
        <child link="cart"/>
        <origin xyz="1000 -10 10" />
        <axis xyz="1 0 0"/>
        <limit lower="-1000" upper="1000" effort="1.0" velocity="1" />
    </joint>
    <link name="cart">
        <visual>
            <origin xyz="0 0 0" rpy="0 0 0" />
            <geometry>
                <mesh filename="package://single_leg_description/meshes/cart.STL"/>
            </geometry>
            <material name="blue">
                <color rgba="0 0 1 0.9"/>
            </material>
        </visual>
    </link>
    <joint name="ankel" type="continuous">
        <parent link="cart"/>
        <child link="calf"/>
        <origin xyz="30 5 60" rpy="0 0 0" />
        <axis xyz="0 1 0"/>
    </joint>
    <link name="calf">
        <visual>
            <origin xyz="-10 0 -10" rpy="0 0 0" />
            <geometry>
                <mesh filename="package://single_leg_description/meshes/calf.STL"/>
            </geometry>
            <material name="red">
                <color rgba="1 0 0 0.4"/>
            </material>
        </visual>
    </link>
    <joint name="knee" type="continuous">
        <parent link="calf"/>
        <child link="thigh"/>
        <origin xyz="0 0 400" rpy="0 0 0" />
        <axis xyz="0 1 0"/>
    </joint>
    <link name="thigh">
        <visual>
            <origin xyz="-50 -30 -50" rpy="0 0 0" />
            <geometry>
                <mesh filename="package://single_leg_description/meshes/thigh.STL"/>
            </geometry>
            <material name="green">
                <color rgba="0 1 0 0.4"/>
            </material>
        </visual>
    </link>
    <joint name="hip" type="continuous">
        <parent link="thigh"/>
        <child link="trunk"/>
        <origin xyz="0 0 500" rpy="0 0 0" />
        <axis xyz="0 1 0"/>
    </joint>
    <link name="trunk">
        <visual>
            <origin xyz="-160 -155 -86" rpy="0 0 0" />
            <geometry>
                <mesh filename="package://single_leg_description/meshes/trunk.STL"/>
            </geometry>
            <material name="">
                <color rgba="1 1 0 0.4"/>
            </material>
        </visual>
    </link>
</robot>
    